Workbook

Sheet train
A1: state | B1: account_length | C1: area_code | D1: international_plan | E1: voice_mail_plan | F1: number_vmail_messages | G1: total_day_minutes | H1: total_day_calls | I1: total_day_charge | J1: total_eve_minutes | K1: total_eve_calls | L1: total_eve_charge | M1: total_night_minutes | N1: total_night_calls | O1: total_night_charge | P1: total_intl_minutes | Q1: total_intl_calls | R1: total_intl_charge | S1: number_customer_service_calls | T1: churn | U1: Churn Numeric | V1: Service Call Group | W1: Account Length Quartile | X1: Intl Charge Group | Y1: Evening Usage Group | Z1: Day Z-Score | AA1: Evening Z-Score | AB1: Night Z-Score | AC1: International Z-Score | AD1: Distance C1 | AE1: Distance C2 | AF1: Distance C3 | AG1: Assigned Cluster | AH1: Voice Mail Message Group | AI1: Churned Day Charge | AJ1: Non-Churned Day Charge | AK1: Intl Plan + Call Group | AL1: Intl Minutes Group | AM1: Intl Plan Numeric | AN1: Area 415 | AO1: Area 510 | AP1: Customer Service Calls | AQ1: Total Day Minutes | AS1: Intercept | AT1: Intl Plan | AU1: Service Calls | AV1: Day Minutes | AY1: Predicted Probability | AZ1: Log Likelihood | BK1: Churn Status | BL1: Count | BM1: Percentage | BO1: Churn | BP1: Churn Numeric
A2: OH | B2: 107 | C2: area_code_415 | D2: no | E2: yes | F2: 26 | G2: 161.6 | H2: 123 | I2: 27.47 | J2: 195.5 | K2: 103 | L2: 16.62 | M2: 254.4 | N2: 103 | O2: 11.45 | P2: 13.7 | Q2: 3 | R2: 3.7 | S2: 1 | T2: no | U2: =IF(T2="yes",1,0) -> 0 | V2: =IF(S2>3,">3 calls","<=3 calls") -> <=3 calls | W2: =IF(B2<=_xlfn.QUARTILE.INC($B$2:$B$4251,1),"Q1", IF(B2<=_xlfn.QUARTILE.INC($B$2:$B$4251,2),"Q2", IF(B2<=_xlfn.QUARTILE.INC($B$2:$B$4251,3),"Q3","Q4"))) -> Q3 | X2: =IF(D2="no","Not Applicable",IF(R2>2.84,"High","Low")) -> Not Applicable | Y2: =IF(J2<=165,"Low",IF(J2<=233,"Medium","High")) -> Medium | Z2: =(G2-AVERAGE($G$2:$G$4251))/_xlfn.STDEV.S($G$2:$G$4251) -> -0.34546899 | AA2: =(J2-AVERAGE($J$2:$J$4251))/_xlfn.STDEV.S($J$2:$J$4251) -> -0.093013944 | AB2: =(M2-AVERAGE($M$2:$M$4251))/_xlfn.STDEV.S($M$2:$M$4251) -> 1.0698773 | AC2: =(P2-AVERAGE($P$2:$P$4251))/_xlfn.STDEV.S($P$2:$P$4251) -> 1.2477545 | AD2: =SQRT((Z2-$BQ$13)^2+(AA2-$BR$13)^2+(AB2-$BS$13)^2+(AC2-$BT$13)^2) -> 3.2538941 | AE2: =SQRT((Z2-$BQ$14)^2+(AA2-$BR$14)^2+(AB2-$BS$14)^2+(AC2-$BT$14)^2) -> 1.6821204 | AF2: =SQRT((Z2-$BQ$15)^2+(AA2-$BR$15)^2+(AB2-$BS$15)^2+(AC2-$BT$15)^2) -> 1.7524929 | AG2: =IF(AD2=MIN(AD2:AF2),"Cluster 1",IF(AE2=MIN(AD2:AF2),"Cluster 2","Cluster 3")) -> Cluster 2 | AH2: =IF(E2="no","Not Applicable",IF(F2=0,"0 messages",IF(F2<=16,"1-16 messages",">16 messages"))) -> >16 messages | AI2: =IF(T2="yes",I2,NA()) -> #N/A | AJ2: =IF(T2="no",I2,NA()) -> 27.47 | AK2: =D2&" - "&IF(Q2<=3,"Low",IF(Q2<=6,"Medium","High")) -> no - Low | AL2: =IF(P2<=8.5,"Q1 - Low",IF(P2<=10.3,"Q2 - Medium",IF(P2<=12,"Q3 - High","Q4 - Very High"))) -> Q4 - Very High | AM2: =IF(D2="yes",1,0) -> 0 | AN2: =IF(C2="area_code_415",1,0) -> 1 | AO2: =IF(C2="area_code_510",1,0) -> 0 | AP2: =S2 -> 1 | AQ2: =G2 -> 161.6 | AS2: 0 | AT2: 0 | AU2: 0 | AV2: 0 | AW2: 0 | AX2: 0 | AY2: =1/(1+EXP(-($AS$4+$AT$4*AM2+$AU$2*AP2+$AV$2*AQ2+$AW$2*AN2+$AX$2*AO2))) -> 0.5 | AZ2: =U2*LN(MAX(AY2,0.0000000001))+(1-U2)*LN(MAX(1-AY2,0.0000000001)) -> -0.69314718 | BK2: yes | BL2: =COUNTIF($T:$T,BK2) -> 598 | BM2: =BL2/COUNTA($T:$T) -> 0.14067278 | BO2: no | BP2: 0
A3: NJ | B3: 137 | C3: area_code_415 | D3: no | E3: no | F3: 0 | G3: 243.4 | H3: 114 | I3: 41.38 | J3: 121.2 | K3: 110 | L3: 10.3 | M3: 162.6 | N3: 104 | O3: 7.32 | P3: 12.2 | Q3: 5 | R3: 3.29 | S3: 0 | T3: no | U3: =IF(T3="yes",1,0) -> 0 | V3: =IF(S3>3,">3 calls","<=3 calls") -> <=3 calls | W3: =IF(B3<=_xlfn.QUARTILE.INC($B$2:$B$4251,1),"Q1", IF(B3<=_xlfn.QUARTILE.INC($B$2:$B$4251,2),"Q2", IF(B3<=_xlfn.QUARTILE.INC($B$2:$B$4251,3),"Q3","Q4"))) -> Q4 | X3: =IF(D3="no","Not Applicable",IF(R3>2.84,"High","Low")) -> Not Applicable | Y3: =IF(J3<=165,"Low",IF(J3<=233,"Medium","High")) -> Low | Z3: =(G3-AVERAGE($G$2:$G$4251))/_xlfn.STDEV.S($G$2:$G$4251) -> 1.1689988 | AA3: =(J3-AVERAGE($J$2:$J$4251))/_xlfn.STDEV.S($J$2:$J$4251) -> -1.5716351 | AB3: =(M3-AVERAGE($M$2:$M$4251))/_xlfn.STDEV.S($M$2:$M$4251) -> -0.75323158 | AC3: =(P3-AVERAGE($P$2:$P$4251))/_xlfn.STDEV.S($P$2:$P$4251) -> 0.70429629 | AD3: =SQRT((Z3-$BQ$13)^2+(AA3-$BR$13)^2+(AB3-$BS$13)^2+(AC3-$BT$13)^2) -> 2.827869 | AE3: =SQRT((Z3-$BQ$14)^2+(AA3-$BR$14)^2+(AB3-$BS$14)^2+(AC3-$BT$14)^2) -> 2.2135912 | AF3: =SQRT((Z3-$BQ$15)^2+(AA3-$BR$15)^2+(AB3-$BS$15)^2+(AC3-$BT$15)^2) -> 3.1309949 | AG3: =IF(AD3=MIN(AD3:AF3),"Cluster 1",IF(AE3=MIN(AD3:AF3),"Cluster 2","Cluster 3")) -> Cluster 2 | AH3: =IF(E3="no","Not Applicable",IF(F3=0,"0 messages",IF(F3<=16,"1-16 messages",">16 messages"))) -> Not Applicable | AI3: =IF(T3="yes",I3,NA()) -> #N/A | AJ3: =IF(T3="no",I3,NA()) -> 41.38 | AK3: =D3&" - "&IF(Q3<=3,"Low",IF(Q3<=6,"Medium","High")) -> no - Medium | AL3: =IF(P3<=8.5,"Q1 - Low",IF(P3<=10.3,"Q2 - Medium",IF(P3<=12,"Q3 - High","Q4 - Very High"))) -> Q4 - Very High | AM3: =IF(D3="yes",1,0) -> 0 | AN3: =IF(C3="area_code_415",1,0) -> 1 | AO3: =IF(C3="area_code_510",1,0) -> 0 | AP3: =S3 -> 0 | AQ3: =G3 -> 243.4 | BJ3: =CORREL(B2:B4251,U2:U4251) -> 0.01937849 | BK3: no | BL3: =COUNTIF($T:$T,BK3) -> 3652 | BM3: =BL3/COUNTA($T:$T) -> 0.85909198 | BO3: yes | BP3: 1 | BR3: Correlation: | BS3: =CORREL(B2:B4251,U2:U4251) -> 0.01937849
A4: OH | B4: 84 | C4: area_code_408 | D4: yes | E4: no | F4: 0 | G4: 299.4 | H4: 71 | I4: 50.9 | J4: 61.9 | K4: 88 | L4: 5.26 | M4: 196.9 | N4: 89 | O4: 8.86 | P4: 6.6 | Q4: 7 | R4: 1.78 | S4: 2 | T4: no | U4: =IF(T4="yes",1,0) -> 0 | V4: =IF(S4>3,">3 calls","<=3 calls") -> <=3 calls | W4: =IF(B4<=_xlfn.QUARTILE.INC($B$2:$B$4251,1),"Q1", IF(B4<=_xlfn.QUARTILE.INC($B$2:$B$4251,2),"Q2", IF(B4<=_xlfn.QUARTILE.INC($B$2:$B$4251,3),"Q3","Q4"))) -> Q2 | X4: =IF(D4="no","Not Applicable",IF(R4>2.84,"High","Low")) -> Low | Y4: =IF(J4<=165,"Low",IF(J4<=233,"Medium","High")) -> Low | Z4: =(G4-AVERAGE($G$2:$G$4251))/_xlfn.STDEV.S($G$2:$G$4251) -> 2.2057983 | AA4: =(J4-AVERAGE($J$2:$J$4251))/_xlfn.STDEV.S($J$2:$J$4251) -> -2.7517459 | AB4: =(M4-AVERAGE($M$2:$M$4251))/_xlfn.STDEV.S($M$2:$M$4251) -> -0.072048197 | AC4: =(P4-AVERAGE($P$2:$P$4251))/_xlfn.STDEV.S($P$2:$P$4251) -> -1.3246144 | AD4: =SQRT((Z4-$BQ$13)^2+(AA4-$BR$13)^2+(AB4-$BS$13)^2+(AC4-$BT$13)^2) -> 3.7831502 | AE4: =SQRT((Z4-$BQ$14)^2+(AA4-$BR$14)^2+(AB4-$BS$14)^2+(AC4-$BT$14)^2) -> 3.7679498 | AF4: =SQRT((Z4-$BQ$15)^2+(AA4-$BR$15)^2+(AB4-$BS$15)^2+(AC4-$BT$15)^2) -> 4.6992198 | AG4: =IF(AD4=MIN(AD4:AF4),"Cluster 1",IF(AE4=MIN(AD4:AF4),"Cluster 2","Cluster 3")) -> Cluster 2 | AH4: =IF(E4="no","Not Applicable",IF(F4=0,"0 messages",IF(F4<=16,"1-16 messages",">16 messages"))) -> Not Applicable | AI4: =IF(T4="yes",I4,NA()) -> #N/A | AJ4: =IF(T4="no",I4,NA()) -> 50.9 | AK4: =D4&" - "&IF(Q4<=3,"Low",IF(Q4<=6,"Medium","High")) -> yes - High | AL4: =IF(P4<=8.5,"Q1 - Low",IF(P4<=10.3,"Q2 - Medium",IF(P4<=12,"Q3 - High","Q4 - Very High"))) -> Q1 - Low | AM4: =IF(D4="yes",1,0) -> 1 | AN4: =IF(C4="area_code_415",1,0) -> 0 | AO4: =IF(C4="area_code_510",1,0) -> 0 | AP4: =S4 -> 2 | AQ4: =G4 -> 299.4
A5: OK | B5: 75 | C5: area_code_415 | D5: yes | E5: no | F5: 0 | G5: 166.7 | H5: 113 | I5: 28.34 | J5: 148.3 | K5: 122 | L5: 12.61 | M5: 186.9 | N5: 121 | O5: 8.41 | P5: 10.1 | Q5: 3 | R5: 2.73 | S5: 3 | T5: no | U5: =IF(T5="yes",1,0) -> 0 | V5: =IF(S5>3,">3 calls","<=3 calls") -> <=3 calls | W5: =IF(B5<=_xlfn.QUARTILE.INC($B$2:$B$4251,1),"Q1", IF(B5<=_xlfn.QUARTILE.INC($B$2:$B$4251,2),"Q2", IF(B5<=_xlfn.QUARTILE.INC($B$2:$B$4251,3),"Q3","Q4"))) -> Q2 | X5: =IF(D5="no","Not Applicable",IF(R5>2.84,"High","Low")) -> Low | Y5: =IF(J5<=165,"Low",IF(J5<=233,"Medium","High")) -> Low | Z5: =(G5-AVERAGE($G$2:$G$4251))/_xlfn.STDEV.S($G$2:$G$4251) -> -0.25104618 | AA5: =(J5-AVERAGE($J$2:$J$4251))/_xlfn.STDEV.S($J$2:$J$4251) -> -1.0323264 | AB5: =(M5-AVERAGE($M$2:$M$4251))/_xlfn.STDEV.S($M$2:$M$4251) -> -0.27064393 | AC5: =(P5-AVERAGE($P$2:$P$4251))/_xlfn.STDEV.S($P$2:$P$4251) -> -0.05654523 | AD5: =SQRT((Z5-$BQ$13)^2+(AA5-$BR$13)^2+(AB5-$BS$13)^2+(AC5-$BT$13)^2) -> 1.408561 | AE5: =SQRT((Z5-$BQ$14)^2+(AA5-$BR$14)^2+(AB5-$BS$14)^2+(AC5-$BT$14)^2) -> 1.0978012 | AF5: =SQRT((Z5-$BQ$15)^2+(AA5-$BR$15)^2+(AB5-$BS$15)^2+(AC5-$BT$15)^2) -> 2.9028075 | AG5: =IF(AD5=MIN(AD5:AF5),"Cluster 1",IF(AE5=MIN(AD5:AF5),"Cluster 2","Cluster 3")) -> Cluster 2 | AH5: =IF(E5="no","Not Applicable",IF(F5=0,"0 messages",IF(F5<=16,"1-16 messages",">16 messages"))) -> Not Applicable | AI5: =IF(T5="yes",I5,NA()) -> #N/A | AJ5: =IF(T5="no",I5,NA()) -> 28.34 | AK5: =D5&" - "&IF(Q5<=3,"Low",IF(Q5<=6,"Medium","High")) -> yes - Low | AL5: =IF(P5<=8.5,"Q1 - Low",IF(P5<=10.3,"Q2 - Medium",IF(P5<=12,"Q3 - High","Q4 - Very High"))) -> Q2 - Medium | AM5: =IF(D5="yes",1,0) -> 1 | AN5: =IF(C5="area_code_415",1,0) -> 1 | AO5: =IF(C5="area_code_510",1,0) -> 0 | AP5: =S5 -> 3 | AQ5: =G5 -> 166.7 | BK5: Churned Average | BL5: =AVERAGEIF($T:$T,"yes",$B:$B) -> 102.13712 | BN5: Correlation: | BO5: =CORREL(H2:H4251,U2:U4251) -> 0.011640422 | BR5: Median: | BS5: {=MEDIAN(IF($D$2:$D$4251="yes",$R$2:$R$4251))} -> 2.84
A6: MA | B6: 121 | C6: area_code_510 | D6: no | E6: yes | F6: 24 | G6: 218.2 | H6: 88 | I6: 37.09 | J6: 348.5 | K6: 108 | L6: 29.62 | M6: 212.6 | N6: 118 | O6: 9.57 | P6: 7.5 | Q6: 7 | R6: 2.03 | S6: 3 | T6: no | U6: =IF(T6="yes",1,0) -> 0 | V6: =IF(S6>3,">3 calls","<=3 calls") -> <=3 calls | W6: =IF(B6<=_xlfn.QUARTILE.INC($B$2:$B$4251,1),"Q1", IF(B6<=_xlfn.QUARTILE.INC($B$2:$B$4251,2),"Q2", IF(B6<=_xlfn.QUARTILE.INC($B$2:$B$4251,3),"Q3","Q4"))) -> Q3 | X6: =IF(D6="no","Not Applicable",IF(R6>2.84,"High","Low")) -> Not Applicable | Y6: =IF(J6<=165,"Low",IF(J6<=233,"Medium","High")) -> High | Z6: =(G6-AVERAGE($G$2:$G$4251))/_xlfn.STDEV.S($G$2:$G$4251) -> 0.70243905 | AA6: =(J6-AVERAGE($J$2:$J$4251))/_xlfn.STDEV.S($J$2:$J$4251) -> 2.9517914 | AB6: =(M6-AVERAGE($M$2:$M$4251))/_xlfn.STDEV.S($M$2:$M$4251) -> 0.23974711 | AC6: =(P6-AVERAGE($P$2:$P$4251))/_xlfn.STDEV.S($P$2:$P$4251) -> -0.9985395 | AD6: =SQRT((Z6-$BQ$13)^2+(AA6-$BR$13)^2+(AB6-$BS$13)^2+(AC6-$BT$13)^2) -> 4.477938 | AE6: =SQRT((Z6-$BQ$14)^2+(AA6-$BR$14)^2+(AB6-$BS$14)^2+(AC6-$BT$14)^2) -> 3.2032878 | AF6: =SQRT((Z6-$BQ$15)^2+(AA6-$BR$15)^2+(AB6-$BS$15)^2+(AC6-$BT$15)^2) -> 2.9103568 | AG6: =IF(AD6=MIN(AD6:AF6),"Cluster 1",IF(AE6=MIN(AD6:AF6),"Cluster 2","Cluster 3")) -> Cluster 3 | AH6: =IF(E6="no","Not Applicable",IF(F6=0,"0 messages",IF(F6<=16,"1-16 messages",">16 messages"))) -> >16 messages | AI6: =IF(T6="yes",I6,NA()) -> #N/A | AJ6: =IF(T6="no",I6,NA()) -> 37.09 | AK6: =D6&" - "&IF(Q6<=3,"Low",IF(Q6<=6,"Medium","High")) -> no - High | AL6: =IF(P6<=8.5,"Q1 - Low",IF(P6<=10.3,"Q2 - Medium",IF(P6<=12,"Q3 - High","Q4 - Very High"))) -> Q1 - Low | AM6: =IF(D6="yes",1,0) -> 0 | AN6: =IF(C6="area_code_415",1,0) -> 0 | AO6: =IF(C6="area_code_510",1,0) -> 1 | AP6: =S6 -> 3 | AQ6: =G6 -> 218.2 | BK6: Non Churned Average | BL6: =AVERAGEIF($T:$T,"no",$B:$B) -> 99.924973
A7: MO | B7: 147 | C7: area_code_415 | D7: yes | E7: no | F7: 0 | G7: 157 | H7: 79 | I7: 26.69 | J7: 103.1 | K7: 94 | L7: 8.76 | M7: 211.8 | N7: 96 | O7: 9.53 | P7: 7.1 | Q7: 6 | R7: 1.92 | S7: 0 | T7: no | U7: =IF(T7="yes",1,0) -> 0 | V7: =IF(S7>3,">3 calls","<=3 calls") -> <=3 calls | W7: =IF(B7<=_xlfn.QUARTILE.INC($B$2:$B$4251,1),"Q1", IF(B7<=_xlfn.QUARTILE.INC($B$2:$B$4251,2),"Q2", IF(B7<=_xlfn.QUARTILE.INC($B$2:$B$4251,3),"Q3","Q4"))) -> Q4 | X7: =IF(D7="no","Not Applicable",IF(R7>2.84,"High","Low")) -> Low | Y7: =IF(J7<=165,"Low",IF(J7<=233,"Medium","High")) -> Low | Z7: =(G7-AVERAGE($G$2:$G$4251))/_xlfn.STDEV.S($G$2:$G$4251) -> -0.43063466 | AA7: =(J7-AVERAGE($J$2:$J$4251))/_xlfn.STDEV.S($J$2:$J$4251) -> -1.9318375 | AB7: =(M7-AVERAGE($M$2:$M$4251))/_xlfn.STDEV.S($M$2:$M$4251) -> 0.22385945 | AC7: =(P7-AVERAGE($P$2:$P$4251))/_xlfn.STDEV.S($P$2:$P$4251) -> -1.1434617 | AD7: =SQRT((Z7-$BQ$13)^2+(AA7-$BR$13)^2+(AB7-$BS$13)^2+(AC7-$BT$13)^2) -> 1.6464845 | AE7: =SQRT((Z7-$BQ$14)^2+(AA7-$BR$14)^2+(AB7-$BS$14)^2+(AC7-$BT$14)^2) -> 2.2967499 | AF7: =SQRT((Z7-$BQ$15)^2+(AA7-$BR$15)^2+(AB7-$BS$15)^2+(AC7-$BT$15)^2) -> 3.9798504 | AG7: =IF(AD7=MIN(AD7:AF7),"Cluster 1",IF(AE7=MIN(AD7:AF7),"Cluster 2","Cluster 3")) -> Cluster 1 | AH7: =IF(E7="no","Not Applicable",IF(F7=0,"0 messages",IF(F7<=16,"1-16 messages",">16 messages"))) -> Not Applicable | AI7: =IF(T7="yes",I7,NA()) -> #N/A | AJ7: =IF(T7="no",I7,NA()) -> 26.69 | AK7: =D7&" - "&IF(Q7<=3,"Low",IF(Q7<=6,"Medium","High")) -> yes - Medium | AL7: =IF(P7<=8.5,"Q1 - Low",IF(P7<=10.3,"Q2 - Medium",IF(P7<=12,"Q3 - High","Q4 - Very High"))) -> Q1 - Low | AM7: =IF(D7="yes",1,0) -> 1 | AN7: =IF(C7="area_code_415",1,0) -> 1 | AO7: =IF(C7="area_code_510",1,0) -> 0 | AP7: =S7 -> 0 | AQ7: =G7 -> 157 | BR7: Q1: | BS7: =_xlfn.QUARTILE.INC($J$2:$J$4251,1) -> 165.925
A8: LA | B8: 117 | C8: area_code_408 | D8: no | E8: no | F8: 0 | G8: 184.5 | H8: 97 | I8: 31.37 | J8: 351.6 | K8: 80 | L8: 29.89 | M8: 215.8 | N8: 90 | O8: 9.71 | P8: 8.7 | Q8: 4 | R8: 2.35 | S8: 1 | T8: no | U8: =IF(T8="yes",1,0) -> 0 | V8: =IF(S8>3,">3 calls","<=3 calls") -> <=3 calls | W8: =IF(B8<=_xlfn.QUARTILE.INC($B$2:$B$4251,1),"Q1", IF(B8<=_xlfn.QUARTILE.INC($B$2:$B$4251,2),"Q2", IF(B8<=_xlfn.QUARTILE.INC($B$2:$B$4251,3),"Q3","Q4"))) -> Q3 | X8: =IF(D8="no","Not Applicable",IF(R8>2.84,"High","Low")) -> Not Applicable | Y8: =IF(J8<=165,"Low",IF(J8<=233,"Medium","High")) -> High | Z8: =(G8-AVERAGE($G$2:$G$4251))/_xlfn.STDEV.S($G$2:$G$4251) -> 0.078507937 | AA8: =(J8-AVERAGE($J$2:$J$4251))/_xlfn.STDEV.S($J$2:$J$4251) -> 3.0134835 | AB8: =(M8-AVERAGE($M$2:$M$4251))/_xlfn.STDEV.S($M$2:$M$4251) -> 0.30329775 | AC8: =(P8-AVERAGE($P$2:$P$4251))/_xlfn.STDEV.S($P$2:$P$4251) -> -0.56377291 | AD8: =SQRT((Z8-$BQ$13)^2+(AA8-$BR$13)^2+(AB8-$BS$13)^2+(AC8-$BT$13)^2) -> 4.3772261 | AE8: =SQRT((Z8-$BQ$14)^2+(AA8-$BR$14)^2+(AB8-$BS$14)^2+(AC8-$BT$14)^2) -> 3.0817326 | AF8: =SQRT((Z8-$BQ$15)^2+(AA8-$BR$15)^2+(AB8-$BS$15)^2+(AC8-$BT$15)^2) -> 2.7989361 | AG8: =IF(AD8=MIN(AD8:AF8),"Cluster 1",IF(AE8=MIN(AD8:AF8),"Cluster 2","Cluster 3")) -> Cluster 3 | AH8: =IF(E8="no","Not Applicable",IF(F8=0,"0 messages",IF(F8<=16,"1-16 messages",">16 messages"))) -> Not Applicable | AI8: =IF(T8="yes",I8,NA()) -> #N/A | AJ8: =IF(T8="no",I8,NA()) -> 31.37 | AK8: =D8&" - "&IF(Q8<=3,"Low",IF(Q8<=6,"Medium","High")) -> no - Medium | AL8: =IF(P8<=8.5,"Q1 - Low",IF(P8<=10.3,"Q2 - Medium",IF(P8<=12,"Q3 - High","Q4 - Very High"))) -> Q2 - Medium | AM8: =IF(D8="yes",1,0) -> 0 | AN8: =IF(C8="area_code_415",1,0) -> 0 | AO8: =IF(C8="area_code_510",1,0) -> 0 | AP8: =S8 -> 1 | AQ8: =G8 -> 184.5 | BL8: Yes | BM8: No | BR8: Q2: | BS8: =_xlfn.QUARTILE.INC($J$2:$J$4251,2) -> 200.7
A9: WV | B9: 141 | C9: area_code_415 | D9: yes | E9: yes | F9: 37 | G9: 258.6 | H9: 84 | I9: 43.96 | J9: 222 | K9: 111 | L9: 18.87 | M9: 326.4 | N9: 97 | O9: 14.69 | P9: 11.2 | Q9: 5 | R9: 3.02 | S9: 0 | T9: no | U9: =IF(T9="yes",1,0) -> 0 | V9: =IF(S9>3,">3 calls","<=3 calls") -> <=3 calls | W9: =IF(B9<=_xlfn.QUARTILE.INC($B$2:$B$4251,1),"Q1", IF(B9<=_xlfn.QUARTILE.INC($B$2:$B$4251,2),"Q2", IF(B9<=_xlfn.QUARTILE.INC($B$2:$B$4251,3),"Q3","Q4"))) -> Q4 | X9: =IF(D9="no","Not Applicable",IF(R9>2.84,"High","Low")) -> High | Y9: =IF(J9<=165,"Low",IF(J9<=233,"Medium","High")) -> Medium | Z9: =(G9-AVERAGE($G$2:$G$4251))/_xlfn.STDEV.S($G$2:$G$4251) -> 1.4504158 | AA9: =(J9-AVERAGE($J$2:$J$4251))/_xlfn.STDEV.S($J$2:$J$4251) -> 0.4343543 | AB9: =(M9-AVERAGE($M$2:$M$4251))/_xlfn.STDEV.S($M$2:$M$4251) -> 2.4997666 | AC9: =(P9-AVERAGE($P$2:$P$4251))/_xlfn.STDEV.S($P$2:$P$4251) -> 0.34199081 | AD9: =SQRT((Z9-$BQ$13)^2+(AA9-$BR$13)^2+(AB9-$BS$13)^2+(AC9-$BT$13)^2) -> 4.7022564 | AE9: =SQRT((Z9-$BQ$14)^2+(AA9-$BR$14)^2+(AB9-$BS$14)^2+(AC9-$BT$14)^2) -> 2.9424752 | AF9: =SQRT((Z9-$BQ$15)^2+(AA9-$BR$15)^2+(AB9-$BS$15)^2+(AC9-$BT$15)^2) -> 1.7902808 | AG9: =IF(AD9=MIN(AD9:AF9),"Cluster 1",IF(AE9=MIN(AD9:AF9),"Cluster 2","Cluster 3")) -> Cluster 3 | AH9: =IF(E9="no","Not Applicable",IF(F9=0,"0 messages",IF(F9<=16,"1-16 messages",">16 messages"))) -> >16 messages | AI9: =IF(T9="yes",I9,NA()) -> #N/A | AJ9: =IF(T9="no",I9,NA()) -> 43.96 | AK9: =D9&" - "&IF(Q9<=3,"Low",IF(Q9<=6,"Medium","High")) -> yes - Medium | AL9: =IF(P9<=8.5,"Q1 - Low",IF(P9<=10.3,"Q2 - Medium",IF(P9<=12,"Q3 - High","Q4 - Very High"))) -> Q3 - High | AM9: =IF(D9="yes",1,0) -> 1 | AN9: =IF(C9="area_code_415",1,0) -> 1 | AO9: =IF(C9="area_code_510",1,0) -> 0 | AP9: =S9 -> 0 | AQ9: =G9 -> 258.6 | BK9: Total customers | BL9: =COUNTIF($D:$D,"yes") -> 396 | BM9: =COUNTIF($D:$D,"no") -> 3854 | BR9: Q3: | BS9: =_xlfn.QUARTILE.INC($J$2:$J$4251,3) -> 233.775
A10: IN | B10: 65 | C10: area_code_415 | D10: no | E10: no | F10: 0 | G10: 129.1 | H10: 137 | I10: 21.95 | J10: 228.5 | K10: 83 | L10: 19.42 | M10: 208.8 | N10: 111 | O10: 9.4 | P10: 12.7 | Q10: 6 | R10: 3.43 | S10: 4 | T10: yes | U10: =IF(T10="yes",1,0) -> 1 | V10: =IF(S10>3,">3 calls","<=3 calls") -> >3 calls | W10: =IF(B10<=_xlfn.QUARTILE.INC($B$2:$B$4251,1),"Q1", IF(B10<=_xlfn.QUARTILE.INC($B$2:$B$4251,2),"Q2", IF(B10<=_xlfn.QUARTILE.INC($B$2:$B$4251,3),"Q3","Q4"))) -> Q1 | X10: =IF(D10="no","Not Applicable",IF(R10>2.84,"High","Low")) -> Not Applicable | Y10: =IF(J10<=165,"Low",IF(J10<=233,"Medium","High")) -> Medium | Z10: =(G10-AVERAGE($G$2:$G$4251))/_xlfn.STDEV.S($G$2:$G$4251) -> -0.94718297 | AA10: =(J10-AVERAGE($J$2:$J$4251))/_xlfn.STDEV.S($J$2:$J$4251) -> 0.56370877 | AB10: =(M10-AVERAGE($M$2:$M$4251))/_xlfn.STDEV.S($M$2:$M$4251) -> 0.16428073 | AC10: =(P10-AVERAGE($P$2:$P$4251))/_xlfn.STDEV.S($P$2:$P$4251) -> 0.88544904 | AD10: =SQRT((Z10-$BQ$13)^2+(AA10-$BR$13)^2+(AB10-$BS$13)^2+(AC10-$BT$13)^2) -> 2.7126449 | AE10: =SQRT((Z10-$BQ$14)^2+(AA10-$BR$14)^2+(AB10-$BS$14)^2+(AC10-$BT$14)^2) -> 1.4233521 | AF10: =SQRT((Z10-$BQ$15)^2+(AA10-$BR$15)^2+(AB10-$BS$15)^2+(AC10-$BT$15)^2) -> 2.1664303 | AG10: =IF(AD10=MIN(AD10:AF10),"Cluster 1",IF(AE10=MIN(AD10:AF10),"Cluster 2","Cluster 3")) -> Cluster 2 | AH10: =IF(E10="no","Not Applicable",IF(F10=0,"0 messages",IF(F10<=16,"1-16 messages",">16 messages"))) -> Not Applicable | AI10: =IF(T10="yes",I10,NA()) -> 21.95 | AJ10: =IF(T10="no",I10,NA()) -> #N/A | AK10: =D10&" - "&IF(Q10<=3,"Low",IF(Q10<=6,"Medium","High")) -> no - Medium | AL10: =IF(P10<=8.5,"Q1 - Low",IF(P10<=10.3,"Q2 - Medium",IF(P10<=12,"Q3 - High","Q4 - Very High"))) -> Q4 - Very High | AM10: =IF(D10="yes",1,0) -> 0 | AN10: =IF(C10="area_code_415",1,0) -> 1 | AO10: =IF(C10="area_code_510",1,0) -> 0 | AP10: =S10 -> 4 | AQ10: =G10 -> 129.1 | BK10: Churned | BL10: =COUNTIFS($D:$D,"yes",$T:$T,"yes") -> 167 | BM10: =COUNTIFS($D:$D,"no",$T:$T,"yes") -> 431
A11: RI | B11: 74 | C11: area_code_415 | D11: no | E11: no | F11: 0 | G11: 187.7 | H11: 127 | I11: 31.91 | J11: 163.4 | K11: 148 | L11: 13.89 | M11: 196 | N11: 94 | O11: 8.82 | P11: 9.1 | Q11: 5 | R11: 2.46 | S11: 0 | T11: no | U11: =IF(T11="yes",1,0) -> 0 | V11: =IF(S11>3,">3 calls","<=3 calls") -> <=3 calls | W11: =IF(B11<=_xlfn.QUARTILE.INC($B$2:$B$4251,1),"Q1", IF(B11<=_xlfn.QUARTILE.INC($B$2:$B$4251,2),"Q2", IF(B11<=_xlfn.QUARTILE.INC($B$2:$B$4251,3),"Q3","Q4"))) -> Q2 | X11: =IF(D11="no","Not Applicable",IF(R11>2.84,"High","Low")) -> Not Applicable | Y11: =IF(J11<=165,"Low",IF(J11<=233,"Medium","High")) -> Low | Z11: =(G11-AVERAGE($G$2:$G$4251))/_xlfn.STDEV.S($G$2:$G$4251) -> 0.13775362 | AA11: =(J11-AVERAGE($J$2:$J$4251))/_xlfn.STDEV.S($J$2:$J$4251) -> -0.73182604 | AB11: =(M11-AVERAGE($M$2:$M$4251))/_xlfn.STDEV.S($M$2:$M$4251) -> -0.089921813 | AC11: =(P11-AVERAGE($P$2:$P$4251))/_xlfn.STDEV.S($P$2:$P$4251) -> -0.41885072 | AD11: =SQRT((Z11-$BQ$13)^2+(AA11-$BR$13)^2+(AB11-$BS$13)^2+(AC11-$BT$13)^2) -> 1.5913445 | AE11: =SQRT((Z11-$BQ$14)^2+(AA11-$BR$14)^2+(AB11-$BS$14)^2+(AC11-$BT$14)^2) -> 0.85910841 | AF11: =SQRT((Z11-$BQ$15)^2+(AA11-$BR$15)^2+(AB11-$BS$15)^2+(AC11-$BT$15)^2) -> 2.635101 | AG11: =IF(AD11=MIN(AD11:AF11),"Cluster 1",IF(AE11=MIN(AD11:AF11),"Cluster 2","Cluster 3")) -> Cluster 2 | AH11: =IF(E11="no","Not Applicable",IF(F11=0,"0 messages",IF(F11<=16,"1-16 messages",">16 messages"))) -> Not Applicable | AI11: =IF(T11="yes",I11,NA()) -> #N/A | AJ11: =IF(T11="no",I11,NA()) -> 31.91 | AK11: =D11&" - "&IF(Q11<=3,"Low",IF(Q11<=6,"Medium","High")) -> no - Medium | AL11: =IF(P11<=8.5,"Q1 - Low",IF(P11<=10.3,"Q2 - Medium",IF(P11<=12,"Q3 - High","Q4 - Very High"))) -> Q2 - Medium | AM11: =IF(D11="yes",1,0) -> 0 | AN11: =IF(C11="area_code_415",1,0) -> 1 | AO11: =IF(C11="area_code_510",1,0) -> 0 | AP11: =S11 -> 0 | AQ11: =G11 -> 187.7 | BK11: Chrun Rate | BL11: =BL10/BL9 -> 0.42171717 | BM11: =BM10/BM9 -> 0.11183186
A12: IA | B12: 168 | C12: area_code_408 | D12: no | E12: no | F12: 0 | G12: 128.8 | H12: 96 | I12: 21.9 | J12: 104.9 | K12: 71 | L12: 8.92 | M12: 141.1 | N12: 128 | O12: 6.35 | P12: 11.2 | Q12: 2 | R12: 3.02 | S12: 1 | T12: no | U12: =IF(T12="yes",1,0) -> 0 | V12: =IF(S12>3,">3 calls","<=3 calls") -> <=3 calls | W12: =IF(B12<=_xlfn.QUARTILE.INC($B$2:$B$4251,1),"Q1", IF(B12<=_xlfn.QUARTILE.INC($B$2:$B$4251,2),"Q2", IF(B12<=_xlfn.QUARTILE.INC($B$2:$B$4251,3),"Q3","Q4"))) -> Q4 | X12: =IF(D12="no","Not Applicable",IF(R12>2.84,"High","Low")) -> Not Applicable | Y12: =IF(J12<=165,"Low",IF(J12<=233,"Medium","High")) -> Low | Z12: =(G12-AVERAGE($G$2:$G$4251))/_xlfn.STDEV.S($G$2:$G$4251) -> -0.95273725 | AA12: =(J12-AVERAGE($J$2:$J$4251))/_xlfn.STDEV.S($J$2:$J$4251) -> -1.8960163 | AB12: =(M12-AVERAGE($M$2:$M$4251))/_xlfn.STDEV.S($M$2:$M$4251) -> -1.1802124 | AC12: =(P12-AVERAGE($P$2:$P$4251))/_xlfn.STDEV.S($P$2:$P$4251) -> 0.34199081 | AD12: =SQRT((Z12-$BQ$13)^2+(AA12-$BR$13)^2+(AB12-$BS$13)^2+(AC12-$BT$13)^2) -> 1.6243444 | AE12: =SQRT((Z12-$BQ$14)^2+(AA12-$BR$14)^2+(AB12-$BS$14)^2+(AC12-$BT$14)^2) -> 2.4520288 | AF12: =SQRT((Z12-$BQ$15)^2+(AA12-$BR$15)^2+(AB12-$BS$15)^2+(AC12-$BT$15)^2) -> 4.1696997 | AG12: =IF(AD12=MIN(AD12:AF12),"Cluster 1",IF(AE12=MIN(AD12:AF12),"Cluster 2","Cluster 3")) -> Cluster 1 | AH12: =IF(E12="no","Not Applicable",IF(F12=0,"0 messages",IF(F12<=16,"1-16 messages",">16 messages"))) -> Not Applicable | AI12: =IF(T12="yes",I12,NA()) -> #N/A | AJ12: =IF(T12="no",I12,NA()) -> 21.9 | AK12: =D12&" - "&IF(Q12<=3,"Low",IF(Q12<=6,"Medium","High")) -> no - Low | AL12: =IF(P12<=8.5,"Q1 - Low",IF(P12<=10.3,"Q2 - Medium",IF(P12<=12,"Q3 - High","Q4 - Very High"))) -> Q3 - High | AM12: =IF(D12="yes",1,0) -> 0 | AN12: =IF(C12="area_code_415",1,0) -> 0 | AO12: =IF(C12="area_code_510",1,0) -> 0 | AP12: =S12 -> 1 | AQ12: =G12 -> 128.8 | BP12: Cluster | BQ12: Day | BR12: Evening | BS12: Night | BT12: International
A13: MT | B13: 95 | C13: area_code_510 | D13: no | E13: no | F13: 0 | G13: 156.6 | H13: 88 | I13: 26.62 | J13: 247.6 | K13: 75 | L13: 21.05 | M13: 192.3 | N13: 115 | O13: 8.65 | P13: 12.3 | Q13: 5 | R13: 3.32 | S13: 3 | T13: no | U13: =IF(T13="yes",1,0) -> 0 | V13: =IF(S13>3,">3 calls","<=3 calls") -> <=3 calls | W13: =IF(B13<=_xlfn.QUARTILE.INC($B$2:$B$4251,1),"Q1", IF(B13<=_xlfn.QUARTILE.INC($B$2:$B$4251,2),"Q2", IF(B13<=_xlfn.QUARTILE.INC($B$2:$B$4251,3),"Q3","Q4"))) -> Q2 | X13: =IF(D13="no","Not Applicable",IF(R13>2.84,"High","Low")) -> Not Applicable | Y13: =IF(J13<=165,"Low",IF(J13<=233,"Medium","High")) -> High | Z13: =(G13-AVERAGE($G$2:$G$4251))/_xlfn.STDEV.S($G$2:$G$4251) -> -0.43804037 | AA13: =(J13-AVERAGE($J$2:$J$4251))/_xlfn.STDEV.S($J$2:$J$4251) -> 0.94381192 | AB13: =(M13-AVERAGE($M$2:$M$4251))/_xlfn.STDEV.S($M$2:$M$4251) -> -0.16340224 | AC13: =(P13-AVERAGE($P$2:$P$4251))/_xlfn.STDEV.S($P$2:$P$4251) -> 0.74052684 | AD13: =SQRT((Z13-$BQ$13)^2+(AA13-$BR$13)^2+(AB13-$BS$13)^2+(AC13-$BT$13)^2) -> 2.7970579 | AE13: =SQRT((Z13-$BQ$14)^2+(AA13-$BR$14)^2+(AB13-$BS$14)^2+(AC13-$BT$14)^2) -> 1.2875328 | AF13: =SQRT((Z13-$BQ$15)^2+(AA13-$BR$15)^2+(AB13-$BS$15)^2+(AC13-$BT$15)^2) -> 1.8686755 | AG13: =IF(AD13=MIN(AD13:AF13),"Cluster 1",IF(AE13=MIN(AD13:AF13),"Cluster 2","Cluster 3")) -> Cluster 2 | AH13: =IF(E13="no","Not Applicable",IF(F13=0,"0 messages",IF(F13<=16,"1-16 messages",">16 messages"))) -> Not Applicable | AI13: =IF(T13="yes",I13,NA()) -> #N/A | AJ13: =IF(T13="no",I13,NA()) -> 26.62 | AK13: =D13&" - "&IF(Q13<=3,"Low",IF(Q13<=6,"Medium","High")) -> no - Medium | AL13: =IF(P13<=8.5,"Q1 - Low",IF(P13<=10.3,"Q2 - Medium",IF(P13<=12,"Q3 - High","Q4 - Very High"))) -> Q4 - Very High | AM13: =IF(D13="yes",1,0) -> 0 | AN13: =IF(C13="area_code_415",1,0) -> 0 | AO13: =IF(C13="area_code_510",1,0) -> 1 | AP13: =S13 -> 3 | AQ13: =G13 -> 156.6 | BK13: Churned | BL13: =AVERAGEIF($T:$T,"yes",$S:$S) -> 2.2759197 | BP13: Cluster 1 | BQ13: -1 | BR13: -1 | BS13: -1 | BT13: -1
A14: NY | B14: 161 | C14: area_code_415 | D14: no | E14: no | F14: 0 | G14: 332.9 | H14: 67 | I14: 56.59 | J14: 317.8 | K14: 97 | L14: 27.01 | M14: 160.6 | N14: 128 | O14: 7.23 | P14: 5.4 | Q14: 9 | R14: 1.46 | S14: 4 | T14: yes | U14: =IF(T14="yes",1,0) -> 1 | V14: =IF(S14>3,">3 calls","<=3 calls") -> >3 calls | W14: =IF(B14<=_xlfn.QUARTILE.INC($B$2:$B$4251,1),"Q1", IF(B14<=_xlfn.QUARTILE.INC($B$2:$B$4251,2),"Q2", IF(B14<=_xlfn.QUARTILE.INC($B$2:$B$4251,3),"Q3","Q4"))) -> Q4 | X14: =IF(D14="no","Not Applicable",IF(R14>2.84,"High","Low")) -> Not Applicable | Y14: =IF(J14<=165,"Low",IF(J14<=233,"Medium","High")) -> High | Z14: =(G14-AVERAGE($G$2:$G$4251))/_xlfn.STDEV.S($G$2:$G$4251) -> 2.8260265 | AA14: =(J14-AVERAGE($J$2:$J$4251))/_xlfn.STDEV.S($J$2:$J$4251) -> 2.3408402 | AB14: =(M14-AVERAGE($M$2:$M$4251))/_xlfn.STDEV.S($M$2:$M$4251) -> -0.79295072 | AC14: =(P14-AVERAGE($P$2:$P$4251))/_xlfn.STDEV.S($P$2:$P$4251) -> -1.759381 | AD14: =SQRT((Z14-$BQ$13)^2+(AA14-$BR$13)^2+(AB14-$BS$13)^2+(AC14-$BT$13)^2) -> 5.1399632 | AE14: =SQRT((Z14-$BQ$14)^2+(AA14-$BR$14)^2+(AB14-$BS$14)^2+(AC14-$BT$14)^2) -> 4.1461007 | AF14: =SQRT((Z14-$BQ$15)^2+(AA14-$BR$15)^2+(AB14-$BS$15)^2+(AC14-$BT$15)^2) -> 3.9951322 | AG14: =IF(AD14=MIN(AD14:AF14),"Cluster 1",IF(AE14=MIN(AD14:AF14),"Cluster 2","Cluster 3")) -> Cluster 3 | AH14: =IF(E14="no","Not Applicable",IF(F14=0,"0 messages",IF(F14<=16,"1-16 messages",">16 messages"))) -> Not Applicable | AI14: =IF(T14="yes",I14,NA()) -> 56.59 | AJ14: =IF(T14="no",I14,NA()) -> #N/A | AK14: =D14&" - "&IF(Q14<=3,"Low",IF(Q14<=6,"Medium","High")) -> no - High | AL14: =IF(P14<=8.5,"Q1 - Low",IF(P14<=10.3,"Q2 - Medium",IF(P14<=12,"Q3 - High","Q4 - Very High"))) -> Q1 - Low | AM14: =IF(D14="yes",1,0) -> 0 | AN14: =IF(C14="area_code_415",1,0) -> 1 | AO14: =IF(C14="area_code_510",1,0) -> 0 | AP14: =S14 -> 4 | AQ14: =G14 -> 332.9 | BK14: Non-churned | BL14: =AVERAGEIF($T:$T,"no",$S:$S) -> 1.4416758 | BP14: Cluster 2 | BQ14: 0 | BR14: 0 | BS14: 0 | BT14: 0
A15: ID | B15: 85 | C15: area_code_408 | D15: no | E15: yes | F15: 27 | G15: 196.4 | H15: 139 | I15: 33.39 | J15: 280.9 | K15: 90 | L15: 23.88 | M15: 89.3 | N15: 75 | O15: 4.02 | P15: 13.8 | Q15: 4 | R15: 3.73 | S15: 1 | T15: no | U15: =IF(T15="yes",1,0) -> 0 | V15: =IF(S15>3,">3 calls","<=3 calls") -> <=3 calls | W15: =IF(B15<=_xlfn.QUARTILE.INC($B$2:$B$4251,1),"Q1", IF(B15<=_xlfn.QUARTILE.INC($B$2:$B$4251,2),"Q2", IF(B15<=_xlfn.QUARTILE.INC($B$2:$B$4251,3),"Q3","Q4"))) -> Q2 | X15: =IF(D15="no","Not Applicable",IF(R15>2.84,"High","Low")) -> Not Applicable | Y15: =IF(J15<=165,"Low",IF(J15<=233,"Medium","High")) -> High | Z15: =(G15-AVERAGE($G$2:$G$4251))/_xlfn.STDEV.S($G$2:$G$4251) -> 0.29882782 | AA15: =(J15-AVERAGE($J$2:$J$4251))/_xlfn.STDEV.S($J$2:$J$4251) -> 1.6065048 | AB15: =(M15-AVERAGE($M$2:$M$4251))/_xlfn.STDEV.S($M$2:$M$4251) -> -2.2089383 | AC15: =(P15-AVERAGE($P$2:$P$4251))/_xlfn.STDEV.S($P$2:$P$4251) -> 1.2839851 | AD15: =SQRT((Z15-$BQ$13)^2+(AA15-$BR$13)^2+(AB15-$BS$13)^2+(AC15-$BT$13)^2) -> 3.8934485 | AE15: =SQRT((Z15-$BQ$14)^2+(AA15-$BR$14)^2+(AB15-$BS$14)^2+(AC15-$BT$14)^2) -> 3.0328505 | AF15: =SQRT((Z15-$BQ$15)^2+(AA15-$BR$15)^2+(AB15-$BS$15)^2+(AC15-$BT$15)^2) -> 3.3522266 | AG15: =IF(AD15=MIN(AD15:AF15),"Cluster 1",IF(AE15=MIN(AD15:AF15),"Cluster 2","Cluster 3")) -> Cluster 2 | AH15: =IF(E15="no","Not Applicable",IF(F15=0,"0 messages",IF(F15<=16,"1-16 messages",">16 messages"))) -> >16 messages | AI15: =IF(T15="yes",I15,NA()) -> #N/A | AJ15: =IF(T15="no",I15,NA()) -> 33.39 | AK15: =D15&" - "&IF(Q15<=3,"Low",IF(Q15<=6,"Medium","High")) -> no - Medium | AL15: =IF(P15<=8.5,"Q1 - Low",IF(P15<=10.3,"Q2 - Medium",IF(P15<=12,"Q3 - High","Q4 - Very High"))) -> Q4 - Very High | AM15: =IF(D15="yes",1,0) -> 0 | AN15: =IF(C15="area_code_415",1,0) -> 0 | AO15: =IF(C15="area_code_510",1,0) -> 0 | AP15: =S15 -> 1 | AQ15: =G15 -> 196.4 | BK15: Difference | BL15: =BL13-BL14 -> 0.83424394 | BP15: Cluster 3 | BQ15: 1 | BR15: 1 | BS15: 1 | BT15: 1
A16: VA | B16: 76 | C16: area_code_510 | D16: no | E16: yes | F16: 33 | G16: 189.7 | H16: 66 | I16: 32.25 | J16: 212.8 | K16: 65 | L16: 18.09 | M16: 165.7 | N16: 108 | O16: 7.46 | P16: 10 | Q16: 5 | R16: 2.7 | S16: 1 | T16: no | U16: =IF(T16="yes",1,0) -> 0 | V16: =IF(S16>3,">3 calls","<=3 calls") -> <=3 calls | W16: =IF(B16<=_xlfn.QUARTILE.INC($B$2:$B$4251,1),"Q1", IF(B16<=_xlfn.QUARTILE.INC($B$2:$B$4251,2),"Q2", IF(B16<=_xlfn.QUARTILE.INC($B$2:$B$4251,3),"Q3","Q4"))) -> Q2 | X16: =IF(D16="no","Not Applicable",IF(R16>2.84,"High","Low")) -> Not Applicable | Y16: =IF(J16<=165,"Low",IF(J16<=233,"Medium","High")) -> Medium | Z16: =(G16-AVERAGE($G$2:$G$4251))/_xlfn.STDEV.S($G$2:$G$4251) -> 0.17478217 | AA16: =(J16-AVERAGE($J$2:$J$4251))/_xlfn.STDEV.S($J$2:$J$4251) -> 0.25126796 | AB16: =(M16-AVERAGE($M$2:$M$4251))/_xlfn.STDEV.S($M$2:$M$4251) -> -0.6916669 | AC16: =(P16-AVERAGE($P$2:$P$4251))/_xlfn.STDEV.S($P$2:$P$4251) -> -0.092775779 | AD16: =SQRT((Z16-$BQ$13)^2+(AA16-$BR$13)^2+(AB16-$BS$13)^2+(AC16-$BT$13)^2) -> 1.965683 | AE16: =SQRT((Z16-$BQ$14)^2+(AA16-$BR$14)^2+(AB16-$BS$14)^2+(AC16-$BT$14)^2) -> 0.76203336 | AF16: =SQRT((Z16-$BQ$15)^2+(AA16-$BR$15)^2+(AB16-$BS$15)^2+(AC16-$BT$15)^2) -> 2.3016255 | AG16: =IF(AD16=MIN(AD16:AF16),"Cluster 1",IF(AE16=MIN(AD16:AF16),"Cluster 2","Cluster 3")) -> Cluster 2 | AH16: =IF(E16="no","Not Applicable",IF(F16=0,"0 messages",IF(F16<=16,"1-16 messages",">16 messages"))) -> >16 messages | AI16: =IF(T16="yes",I16,NA()) -> #N/A | AJ16: =IF(T16="no",I16,NA()) -> 32.25 | AK16: =D16&" - "&IF(Q16<=3,"Low",IF(Q16<=6,"Medium","High")) -> no - Medium | AL16: =IF(P16<=8.5,"Q1 - Low",IF(P16<=10.3,"Q2 - Medium",IF(P16<=12,"Q3 - High","Q4 - Very High"))) -> Q2 - Medium | AM16: =IF(D16="yes",1,0) -> 0 | AN16: =IF(C16="area_code_415",1,0) -> 0 | AO16: =IF(C16="area_code_510",1,0) -> 1 | AP16: =S16 -> 1 | AQ16: =G16 -> 189.7 | BP16: q9
A17: TX | B17: 73 | C17: area_code_415 | D17: no | E17: no | F17: 0 | G17: 224.4 | H17: 90 | I17: 38.15 | J17: 159.5 | K17: 88 | L17: 13.56 | M17: 192.8 | N17: 74 | O17: 8.68 | P17: 13 | Q17: 2 | R17: 3.51 | S17: 1 | T17: no | U17: =IF(T17="yes",1,0) -> 0 | V17: =IF(S17>3,">3 calls","<=3 calls") -> <=3 calls | W17: =IF(B17<=_xlfn.QUARTILE.INC($B$2:$B$4251,1),"Q1", IF(B17<=_xlfn.QUARTILE.INC($B$2:$B$4251,2),"Q2", IF(B17<=_xlfn.QUARTILE.INC($B$2:$B$4251,3),"Q3","Q4"))) -> Q1 | X17: =IF(D17="no","Not Applicable",IF(R17>2.84,"High","Low")) -> Not Applicable | Y17: =IF(J17<=165,"Low",IF(J17<=233,"Medium","High")) -> Low | Z17: =(G17-AVERAGE($G$2:$G$4251))/_xlfn.STDEV.S($G$2:$G$4251) -> 0.81722756 | AA17: =(J17-AVERAGE($J$2:$J$4251))/_xlfn.STDEV.S($J$2:$J$4251) -> -0.80943872 | AB17: =(M17-AVERAGE($M$2:$M$4251))/_xlfn.STDEV.S($M$2:$M$4251) -> -0.15347245 | AC17: =(P17-AVERAGE($P$2:$P$4251))/_xlfn.STDEV.S($P$2:$P$4251) -> 0.99414068 | AD17: =SQRT((Z17-$BQ$13)^2+(AA17-$BR$13)^2+(AB17-$BS$13)^2+(AC17-$BT$13)^2) -> 2.8340493 | AE17: =SQRT((Z17-$BQ$14)^2+(AA17-$BR$14)^2+(AB17-$BS$14)^2+(AC17-$BT$14)^2) -> 1.528045 | AF17: =SQRT((Z17-$BQ$15)^2+(AA17-$BR$15)^2+(AB17-$BS$15)^2+(AC17-$BT$15)^2) -> 2.1536033 | AG17: =IF(AD17=MIN(AD17:AF17),"Cluster 1",IF(AE17=MIN(AD17:AF17),"Cluster 2","Cluster 3")) -> Cluster 2 | AH17: =IF(E17="no","Not Applicable",IF(F17=0,"0 messages",IF(F17<=16,"1-16 messages",">16 messages"))) -> Not Applicable | AI17: =IF(T17="yes",I17,NA()) -> #N/A | AJ17: =IF(T17="no",I17,NA()) -> 38.15 | AK17: =D17&" - "&IF(Q17<=3,"Low",IF(Q17<=6,"Medium","High")) -> no - Low | AL17: =IF(P17<=8.5,"Q1 - Low",IF(P17<=10.3,"Q2 - Medium",IF(P17<=12,"Q3 - High","Q4 - Very High"))) -> Q4 - Very High | AM17: =IF(D17="yes",1,0) -> 0 | AN17: =IF(C17="area_code_415",1,0) -> 1 | AO17: =IF(C17="area_code_510",1,0) -> 0 | AP17: =S17 -> 1 | AQ17: =G17 -> 224.4 | BK17: Churn Status | BL17: Avg Day Charge | BM17: Avg Evening Charge | BN17: Avg Night Charge | BP17: Q1: | BQ17: =_xlfn.QUARTILE.INC($Q$2:$Q$4251,1) -> 3
A18: FL | B18: 147 | C18: area_code_415 | D18: no | E18: no | F18: 0 | G18: 155.1 | H18: 117 | I18: 26.37 | J18: 239.7 | K18: 93 | L18: 20.37 | M18: 208.8 | N18: 133 | O18: 9.4 | P18: 10.6 | Q18: 4 | R18: 2.86 | S18: 0 | T18: no | U18: =IF(T18="yes",1,0) -> 0 | V18: =IF(S18>3,">3 calls","<=3 calls") -> <=3 calls | W18: =IF(B18<=_xlfn.QUARTILE.INC($B$2:$B$4251,1),"Q1", IF(B18<=_xlfn.QUARTILE.INC($B$2:$B$4251,2),"Q2", IF(B18<=_xlfn.QUARTILE.INC($B$2:$B$4251,3),"Q3","Q4"))) -> Q4 | X18: =IF(D18="no","Not Applicable",IF(R18>2.84,"High","Low")) -> Not Applicable | Y18: =IF(J18<=165,"Low",IF(J18<=233,"Medium","High")) -> High | Z18: =(G18-AVERAGE($G$2:$G$4251))/_xlfn.STDEV.S($G$2:$G$4251) -> -0.46581178 | AA18: =(J18-AVERAGE($J$2:$J$4251))/_xlfn.STDEV.S($J$2:$J$4251) -> 0.78659648 | AB18: =(M18-AVERAGE($M$2:$M$4251))/_xlfn.STDEV.S($M$2:$M$4251) -> 0.16428073 | AC18: =(P18-AVERAGE($P$2:$P$4251))/_xlfn.STDEV.S($P$2:$P$4251) -> 0.12460751 | AD18: =SQRT((Z18-$BQ$13)^2+(AA18-$BR$13)^2+(AB18-$BS$13)^2+(AC18-$BT$13)^2) -> 2.469327 | AE18: =SQRT((Z18-$BQ$14)^2+(AA18-$BR$14)^2+(AB18-$BS$14)^2+(AC18-$BT$14)^2) -> 0.93713917 | AF18: =SQRT((Z18-$BQ$15)^2+(AA18-$BR$15)^2+(AB18-$BS$15)^2+(AC18-$BT$15)^2) -> 1.9128209 | AG18: =IF(AD18=MIN(AD18:AF18),"Cluster 1",IF(AE18=MIN(AD18:AF18),"Cluster 2","Cluster 3")) -> Cluster 2 | AH18: =IF(E18="no","Not Applicable",IF(F18=0,"0 messages",IF(F18<=16,"1-16 messages",">16 messages"))) -> Not Applicable | AI18: =IF(T18="yes",I18,NA()) -> #N/A | AJ18: =IF(T18="no",I18,NA()) -> 26.37 | AK18: =D18&" - "&IF(Q18<=3,"Low",IF(Q18<=6,"Medium","High")) -> no - Medium | AL18: =IF(P18<=8.5,"Q1 - Low",IF(P18<=10.3,"Q2 - Medium",IF(P18<=12,"Q3 - High","Q4 - Very High"))) -> Q3 - High | AM18: =IF(D18="yes",1,0) -> 0 | AN18: =IF(C18="area_code_415",1,0) -> 1 | AO18: =IF(C18="area_code_510",1,0) -> 0 | AP18: =S18 -> 0 | AQ18: =G18 -> 155.1 | BK18: Yes | BL18: =AVERAGEIF($T:$T,"yes",$H:$H) -> 100.47826 | BM18: =AVERAGEIF($T:$T,"yes",$K:$K) -> 99.841137 | BN18: =AVERAGEIF($T:$T,"yes",$N:$N) -> 99.20903 | BP18: Q2: | BQ18: =_xlfn.QUARTILE.INC($Q$2:$Q$4251,2) -> 4
A19: CO | B19: 77 | C19: area_code_408 | D19: no | E19: no | F19: 0 | G19: 62.4 | H19: 89 | I19: 10.61 | J19: 169.9 | K19: 121 | L19: 14.44 | M19: 209.6 | N19: 64 | O19: 9.43 | P19: 5.7 | Q19: 6 | R19: 1.54 | S19: 5 | T19: yes | U19: =IF(T19="yes",1,0) -> 1 | V19: =IF(S19>3,">3 calls","<=3 calls") -> >3 calls | W19: =IF(B19<=_xlfn.QUARTILE.INC($B$2:$B$4251,1),"Q1", IF(B19<=_xlfn.QUARTILE.INC($B$2:$B$4251,2),"Q2", IF(B19<=_xlfn.QUARTILE.INC($B$2:$B$4251,3),"Q3","Q4"))) -> Q2 | X19: =IF(D19="no","Not Applicable",IF(R19>2.84,"High","Low")) -> Not Applicable | Y19: =IF(J19<=165,"Low",IF(J19<=233,"Medium","High")) -> Medium | Z19: =(G19-AVERAGE($G$2:$G$4251))/_xlfn.STDEV.S($G$2:$G$4251) -> -2.1820852 | AA19: =(J19-AVERAGE($J$2:$J$4251))/_xlfn.STDEV.S($J$2:$J$4251) -> -0.60247157 | AB19: =(M19-AVERAGE($M$2:$M$4251))/_xlfn.STDEV.S($M$2:$M$4251) -> 0.18016839 | AC19: =(P19-AVERAGE($P$2:$P$4251))/_xlfn.STDEV.S($P$2:$P$4251) -> -1.6506894 | AD19: =SQRT((Z19-$BQ$13)^2+(AA19-$BR$13)^2+(AB19-$BS$13)^2+(AC19-$BT$13)^2) -> 1.8361776 | AE19: =SQRT((Z19-$BQ$14)^2+(AA19-$BR$14)^2+(AB19-$BS$14)^2+(AC19-$BT$14)^2) -> 2.8074372 | AF19: =SQRT((Z19-$BQ$15)^2+(AA19-$BR$15)^2+(AB19-$BS$15)^2+(AC19-$BT$15)^2) -> 4.5157346 | AG19: =IF(AD19=MIN(AD19:AF19),"Cluster 1",IF(AE19=MIN(AD19:AF19),"Cluster 2","Cluster 3")) -> Cluster 1 | AH19: =IF(E19="no","Not Applicable",IF(F19=0,"0 messages",IF(F19<=16,"1-16 messages",">16 messages"))) -> Not Applicable | AI19: =IF(T19="yes",I19,NA()) -> 10.61 | AJ19: =IF(T19="no",I19,NA()) -> #N/A | AK19: =D19&" - "&IF(Q19<=3,"Low",IF(Q19<=6,"Medium","High")) -> no - Medium | AL19: =IF(P19<=8.5,"Q1 - Low",IF(P19<=10.3,"Q2 - Medium",IF(P19<=12,"Q3 - High","Q4 - Very High"))) -> Q1 - Low | AM19: =IF(D19="yes",1,0) -> 0 | AN19: =IF(C19="area_code_415",1,0) -> 0 | AO19: =IF(C19="area_code_510",1,0) -> 0 | AP19: =S19 -> 5 | AQ19: =G19 -> 62.4 | BK19: No | BL19: =AVERAGEIF($T:$T,"no",$H:$H) -> 99.813801 | BM19: =AVERAGEIF($T:$T,"no",$K:$K) -> 100.23138 | BN19: =AVERAGEIF($T:$T,"no",$N:$N) -> 99.942771 | BP19: Q3: | BQ19: =_xlfn.QUARTILE.INC($Q$2:$Q$4251,3) -> 6
A20: AZ | B20: 130 | C20: area_code_415 | D20: no | E20: no | F20: 0 | G20: 183 | H20: 112 | I20: 31.11 | J20: 72.9 | K20: 99 | L20: 6.2 | M20: 181.8 | N20: 78 | O20: 8.18 | P20: 9.5 | Q20: 19 | R20: 2.57 | S20: 0 | T20: no | U20: =IF(T20="yes",1,0) -> 0 | V20: =IF(S20>3,">3 calls","<=3 calls") -> <=3 calls | W20: =IF(B20<=_xlfn.QUARTILE.INC($B$2:$B$4251,1),"Q1", IF(B20<=_xlfn.QUARTILE.INC($B$2:$B$4251,2),"Q2", IF(B20<=_xlfn.QUARTILE.INC($B$2:$B$4251,3),"Q3","Q4"))) -> Q4 | X20: =IF(D20="no","Not Applicable",IF(R20>2.84,"High","Low")) -> Not Applicable | Y20: =IF(J20<=165,"Low",IF(J20<=233,"Medium","High")) -> Low | Z20: =(G20-AVERAGE($G$2:$G$4251))/_xlfn.STDEV.S($G$2:$G$4251) -> 0.050736523 | AA20: =(J20-AVERAGE($J$2:$J$4251))/_xlfn.STDEV.S($J$2:$J$4251) -> -2.5328383 | AB20: =(M20-AVERAGE($M$2:$M$4251))/_xlfn.STDEV.S($M$2:$M$4251) -> -0.37192776 | AC20: =(P20-AVERAGE($P$2:$P$4251))/_xlfn.STDEV.S($P$2:$P$4251) -> -0.27392852 | AD20: =SQRT((Z20-$BQ$13)^2+(AA20-$BR$13)^2+(AB20-$BS$13)^2+(AC20-$BT$13)^2) -> 2.0917206 | AE20: =SQRT((Z20-$BQ$14)^2+(AA20-$BR$14)^2+(AB20-$BS$14)^2+(AC20-$BT$14)^2) -> 2.5751138 | AF20: =SQRT((Z20-$BQ$15)^2+(AA20-$BR$15)^2+(AB20-$BS$15)^2+(AC20-$BT$15)^2) -> 4.109395 | AG20: =IF(AD20=MIN(AD20:AF20),"Cluster 1",IF(AE20=MIN(AD20:AF20),"Cluster 2","Cluster 3")) -> Cluster 1 | AH20: =IF(E20="no","Not Applicable",IF(F20=0,"0 messages",IF(F20<=16,"1-16 messages",">16 messages"))) -> Not Applicable | AI20: =IF(T20="yes",I20,NA()) -> #N/A | AJ20: =IF(T20="no",I20,NA()) -> 31.11 | AK20: =D20&" - "&IF(Q20<=3,"Low",IF(Q20<=6,"Medium","High")) -> no - High | AL20: =IF(P20<=8.5,"Q1 - Low",IF(P20<=10.3,"Q2 - Medium",IF(P20<=12,"Q3 - High","Q4 - Very High"))) -> Q2 - Medium | AM20: =IF(D20="yes",1,0) -> 0 | AN20: =IF(C20="area_code_415",1,0) -> 1 | AO20: =IF(C20="area_code_510",1,0) -> 0 | AP20: =S20 -> 0 | AQ20: =G20 -> 183
A21: SC | B21: 111 | C21: area_code_415 | D21: no | E21: no | F21: 0 | G21: 110.4 | H21: 103 | I21: 18.77 | J21: 137.3 | K21: 102 | L21: 11.67 | M21: 189.6 | N21: 105 | O21: 8.53 | P21: 7.7 | Q21: 6 | R21: 2.08 | S21: 2 | T21: no | U21: =IF(T21="yes",1,0) -> 0 | V21: =IF(S21>3,">3 calls","<=3 calls") -> <=3 calls | W21: =IF(B21<=_xlfn.QUARTILE.INC($B$2:$B$4251,1),"Q1", IF(B21<=_xlfn.QUARTILE.INC($B$2:$B$4251,2),"Q2", IF(B21<=_xlfn.QUARTILE.INC($B$2:$B$4251,3),"Q3","Q4"))) -> Q3 | X21: =IF(D21="no","Not Applicable",IF(R21>2.84,"High","Low")) -> Not Applicable | Y21: =IF(J21<=165,"Low",IF(J21<=233,"Medium","High")) -> Low | Z21: =(G21-AVERAGE($G$2:$G$4251))/_xlfn.STDEV.S($G$2:$G$4251) -> -1.2933999 | AA21: =(J21-AVERAGE($J$2:$J$4251))/_xlfn.STDEV.S($J$2:$J$4251) -> -1.251234 | AB21: =(M21-AVERAGE($M$2:$M$4251))/_xlfn.STDEV.S($M$2:$M$4251) -> -0.21702309 | AC21: =(P21-AVERAGE($P$2:$P$4251))/_xlfn.STDEV.S($P$2:$P$4251) -> -0.9260784 | AD21: =SQRT((Z21-$BQ$13)^2+(AA21-$BR$13)^2+(AB21-$BS$13)^2+(AC21-$BT$13)^2) -> 0.87619592 | AE21: =SQRT((Z21-$BQ$14)^2+(AA21-$BR$14)^2+(AB21-$BS$14)^2+(AC21-$BT$14)^2) -> 2.0354828 | AF21: =SQRT((Z21-$BQ$15)^2+(AA21-$BR$15)^2+(AB21-$BS$15)^2+(AC21-$BT$15)^2) -> 3.9393732 | AG21: =IF(AD21=MIN(AD21:AF21),"Cluster 1",IF(AE21=MIN(AD21:AF21),"Cluster 2","Cluster 3")) -> Cluster 1 | AH21: =IF(E21="no","Not Applicable",IF(F21=0,"0 messages",IF(F21<=16,"1-16 messages",">16 messages"))) -> Not Applicable | AI21: =IF(T21="yes",I21,NA()) -> #N/A | AJ21: =IF(T21="no",I21,NA()) -> 18.77 | AK21: =D21&" - "&IF(Q21<=3,"Low",IF(Q21<=6,"Medium","High")) -> no - Medium | AL21: =IF(P21<=8.5,"Q1 - Low",IF(P21<=10.3,"Q2 - Medium",IF(P21<=12,"Q3 - High","Q4 - Very High"))) -> Q1 - Low | AM21: =IF(D21="yes",1,0) -> 0 | AN21: =IF(C21="area_code_415",1,0) -> 1 | AO21: =IF(C21="area_code_510",1,0) -> 0 | AP21: =S21 -> 2 | AQ21: =G21 -> 110.4 | BK21: Churn Status | BL21: Avg Total Day Minutes | BP21: AQ1:
A22: VA | B22: 132 | C22: area_code_510 | D22: no | E22: no | F22: 0 | G22: 81.1 | H22: 86 | I22: 13.79 | J22: 245.2 | K22: 72 | L22: 20.84 | M22: 237 | N22: 115 | O22: 10.67 | P22: 10.3 | Q22: 2 | R22: 2.78 | S22: 0 | T22: no | U22: =IF(T22="yes",1,0) -> 0 | V22: =IF(S22>3,">3 calls","<=3 calls") -> <=3 calls | W22: =IF(B22<=_xlfn.QUARTILE.INC($B$2:$B$4251,1),"Q1", IF(B22<=_xlfn.QUARTILE.INC($B$2:$B$4251,2),"Q2", IF(B22<=_xlfn.QUARTILE.INC($B$2:$B$4251,3),"Q3","Q4"))) -> Q4 | X22: =IF(D22="no","Not Applicable",IF(R22>2.84,"High","Low")) -> Not Applicable | Y22: =IF(J22<=165,"Low",IF(J22<=233,"Medium","High")) -> High | Z22: =(G22-AVERAGE($G$2:$G$4251))/_xlfn.STDEV.S($G$2:$G$4251) -> -1.8358682 | AA22: =(J22-AVERAGE($J$2:$J$4251))/_xlfn.STDEV.S($J$2:$J$4251) -> 0.89605027 | AB22: =(M22-AVERAGE($M$2:$M$4251))/_xlfn.STDEV.S($M$2:$M$4251) -> 0.72432071 | AC22: =(P22-AVERAGE($P$2:$P$4251))/_xlfn.STDEV.S($P$2:$P$4251) -> 0.015915867 | AD22: =SQRT((Z22-$BQ$13)^2+(AA22-$BR$13)^2+(AB22-$BS$13)^2+(AC22-$BT$13)^2) -> 2.880807 | AE22: =SQRT((Z22-$BQ$14)^2+(AA22-$BR$14)^2+(AB22-$BS$14)^2+(AC22-$BT$14)^2) -> 2.1675359 | AF22: =SQRT((Z22-$BQ$15)^2+(AA22-$BR$15)^2+(AB22-$BS$15)^2+(AC22-$BT$15)^2) -> 3.0161855 | AG22: =IF(AD22=MIN(AD22:AF22),"Cluster 1",IF(AE22=MIN(AD22:AF22),"Cluster 2","Cluster 3")) -> Cluster 2 | AH22: =IF(E22="no","Not Applicable",IF(F22=0,"0 messages",IF(F22<=16,"1-16 messages",">16 messages"))) -> Not Applicable | AI22: =IF(T22="yes",I22,NA()) -> #N/A | AJ22: =IF(T22="no",I22,NA()) -> 13.79 | AK22: =D22&" - "&IF(Q22<=3,"Low",IF(Q22<=6,"Medium","High")) -> no - Low | AL22: =IF(P22<=8.5,"Q1 - Low",IF(P22<=10.3,"Q2 - Medium",IF(P22<=12,"Q3 - High","Q4 - Very High"))) -> Q2 - Medium | AM22: =IF(D22="yes",1,0) -> 0 | AN22: =IF(C22="area_code_415",1,0) -> 0 | AO22: =IF(C22="area_code_510",1,0) -> 1 | AP22: =S22 -> 0 | AQ22: =G22 -> 81.1 | BK22: Yes | BL22: =AVERAGEIF($T:$T,"yes",$G:$G) -> 208.99013 | BP22: q1 | BQ22: =_xlfn.QUARTILE.INC($P$2:$P$4251,1) -> 8.5
A23: WY | B23: 57 | C23: area_code_408 | D23: no | E23: yes | F23: 39 | G23: 213 | H23: 115 | I23: 36.21 | J23: 191.1 | K23: 112 | L23: 16.24 | M23: 182.7 | N23: 115 | O23: 8.22 | P23: 9.5 | Q23: 3 | R23: 2.57 | S23: 0 | T23: no | U23: =IF(T23="yes",1,0) -> 0 | V23: =IF(S23>3,">3 calls","<=3 calls") -> <=3 calls | W23: =IF(B23<=_xlfn.QUARTILE.INC($B$2:$B$4251,1),"Q1", IF(B23<=_xlfn.QUARTILE.INC($B$2:$B$4251,2),"Q2", IF(B23<=_xlfn.QUARTILE.INC($B$2:$B$4251,3),"Q3","Q4"))) -> Q1 | X23: =IF(D23="no","Not Applicable",IF(R23>2.84,"High","Low")) -> Not Applicable | Y23: =IF(J23<=165,"Low",IF(J23<=233,"Medium","High")) -> Medium | Z23: =(G23-AVERAGE($G$2:$G$4251))/_xlfn.STDEV.S($G$2:$G$4251) -> 0.60616481 | AA23: =(J23-AVERAGE($J$2:$J$4251))/_xlfn.STDEV.S($J$2:$J$4251) -> -0.18057697 | AB23: =(M23-AVERAGE($M$2:$M$4251))/_xlfn.STDEV.S($M$2:$M$4251) -> -0.35405414 | AC23: =(P23-AVERAGE($P$2:$P$4251))/_xlfn.STDEV.S($P$2:$P$4251) -> -0.27392852 | AD23: =SQRT((Z23-$BQ$13)^2+(AA23-$BR$13)^2+(AB23-$BS$13)^2+(AC23-$BT$13)^2) -> 2.0483274 | AE23: =SQRT((Z23-$BQ$14)^2+(AA23-$BR$14)^2+(AB23-$BS$14)^2+(AC23-$BT$14)^2) -> 0.7748774 | AF23: =SQRT((Z23-$BQ$15)^2+(AA23-$BR$15)^2+(AB23-$BS$15)^2+(AC23-$BT$15)^2) -> 2.2372359 | AG23: =IF(AD23=MIN(AD23:AF23),"Cluster 1",IF(AE23=MIN(AD23:AF23),"Cluster 2","Cluster 3")) -> Cluster 2 | AH23: =IF(E23="no","Not Applicable",IF(F23=0,"0 messages",IF(F23<=16,"1-16 messages",">16 messages"))) -> >16 messages | AI23: =IF(T23="yes",I23,NA()) -> #N/A | AJ23: =IF(T23="no",I23,NA()) -> 36.21 | AK23: =D23&" - "&IF(Q23<=3,"Low",IF(Q23<=6,"Medium","High")) -> no - Low | AL23: =IF(P23<=8.5,"Q1 - Low",IF(P23<=10.3,"Q2 - Medium",IF(P23<=12,"Q3 - High","Q4 - Very High"))) -> Q2 - Medium | AM23: =IF(D23="yes",1,0) -> 0 | AN23: =IF(C23="area_code_415",1,0) -> 0 | AO23: =IF(C23="area_code_510",1,0) -> 0 | AP23: =S23 -> 0 | AQ23: =G23 -> 213 | BK23: No | BL23: =AVERAGEIF($T:$T,"no",$G:$G) -> 175.55509 | BP23: q2 | BQ23: =_xlfn.QUARTILE.INC($P$2:$P$4251,2) -> 10.3
A24: MT | B24: 54 | C24: area_code_408 | D24: no | E24: no | F24: 0 | G24: 134.3 | H24: 73 | I24: 22.83 | J24: 155.5 | K24: 100 | L24: 13.22 | M24: 102.1 | N24: 68 | O24: 4.59 | P24: 14.7 | Q24: 4 | R24: 3.97 | S24: 3 | T24: no | U24: =IF(T24="yes",1,0) -> 0 | V24: =IF(S24>3,">3 calls","<=3 calls") -> <=3 calls | W24: =IF(B24<=_xlfn.QUARTILE.INC($B$2:$B$4251,1),"Q1", IF(B24<=_xlfn.QUARTILE.INC($B$2:$B$4251,2),"Q2", IF(B24<=_xlfn.QUARTILE.INC($B$2:$B$4251,3),"Q3","Q4"))) -> Q1 | X24: =IF(D24="no","Not Applicable",IF(R24>2.84,"High","Low")) -> Not Applicable | Y24: =IF(J24<=165,"Low",IF(J24<=233,"Medium","High")) -> Low | Z24: =(G24-AVERAGE($G$2:$G$4251))/_xlfn.STDEV.S($G$2:$G$4251) -> -0.85090873 | AA24: =(J24-AVERAGE($J$2:$J$4251))/_xlfn.STDEV.S($J$2:$J$4251) -> -0.88904148 | AB24: =(M24-AVERAGE($M$2:$M$4251))/_xlfn.STDEV.S($M$2:$M$4251) -> -1.9547358 | AC24: =(P24-AVERAGE($P$2:$P$4251))/_xlfn.STDEV.S($P$2:$P$4251) -> 1.61006 | AD24: =SQRT((Z24-$BQ$13)^2+(AA24-$BR$13)^2+(AB24-$BS$13)^2+(AC24-$BT$13)^2) -> 2.7854037 | AE24: =SQRT((Z24-$BQ$14)^2+(AA24-$BR$14)^2+(AB24-$BS$14)^2+(AC24-$BT$14)^2) -> 2.8156217 | AF24: =SQRT((Z24-$BQ$15)^2+(AA24-$BR$15)^2+(AB24-$BS$15)^2+(AC24-$BT$15)^2) -> 4.0121039 | AG24: =IF(AD24=MIN(AD24:AF24),"Cluster 1",IF(AE24=MIN(AD24:AF24),"Cluster 2","Cluster 3")) -> Cluster 1 | AH24: =IF(E24="no","Not Applicable",IF(F24=0,"0 messages",IF(F24<=16,"1-16 messages",">16 messages"))) -> Not Applicable | AI24: =IF(T24="yes",I24,NA()) -> #N/A | AJ24: =IF(T24="no",I24,NA()) -> 22.83 | AK24: =D24&" - "&IF(Q24<=3,"Low",IF(Q24<=6,"Medium","High")) -> no - Medium | AL24: =IF(P24<=8.5,"Q1 - Low",IF(P24<=10.3,"Q2 - Medium",IF(P24<=12,"Q3 - High","Q4 - Very High"))) -> Q4 - Very High | AM24: =IF(D24="yes",1,0) -> 0 | AN24: =IF(C24="area_code_415",1,0) -> 0 | AO24: =IF(C24="area_code_510",1,0) -> 0 | AP24: =S24 -> 3 | AQ24: =G24 -> 134.3 | BP24: q3 | BQ24: =_xlfn.QUARTILE.INC($P$2:$P$4251,3) -> 12
A25: MO | B25: 20 | C25: area_code_415 | D25: no | E25: no | F25: 0 | G25: 190 | H25: 109 | I25: 32.3 | J25: 258.2 | K25: 84 | L25: 21.95 | M25: 181.5 | N25: 102 | O25: 8.17 | P25: 6.3 | Q25: 6 | R25: 1.7 | S25: 0 | T25: no | U25: =IF(T25="yes",1,0) -> 0 | V25: =IF(S25>3,">3 calls","<=3 calls") -> <=3 calls | W25: =IF(B25<=_xlfn.QUARTILE.INC($B$2:$B$4251,1),"Q1", IF(B25<=_xlfn.QUARTILE.INC($B$2:$B$4251,2),"Q2", IF(B25<=_xlfn.QUARTILE.INC($B$2:$B$4251,3),"Q3","Q4"))) -> Q1 | X25: =IF(D25="no","Not Applicable",IF(R25>2.84,"High","Low")) -> Not Applicable | Y25: =IF(J25<=165,"Low",IF(J25<=233,"Medium","High")) -> High | Z25: =(G25-AVERAGE($G$2:$G$4251))/_xlfn.STDEV.S($G$2:$G$4251) -> 0.18033646 | AA25: =(J25-AVERAGE($J$2:$J$4251))/_xlfn.STDEV.S($J$2:$J$4251) -> 1.1547592 | AB25: =(M25-AVERAGE($M$2:$M$4251))/_xlfn.STDEV.S($M$2:$M$4251) -> -0.37788563 | AC25: =(P25-AVERAGE($P$2:$P$4251))/_xlfn.STDEV.S($P$2:$P$4251) -> -1.4333061 | AD25: =SQRT((Z25-$BQ$13)^2+(AA25-$BR$13)^2+(AB25-$BS$13)^2+(AC25-$BT$13)^2) -> 2.5711791 | AE25: =SQRT((Z25-$BQ$14)^2+(AA25-$BR$14)^2+(AB25-$BS$14)^2+(AC25-$BT$14)^2) -> 1.8876318 | AF25: =SQRT((Z25-$BQ$15)^2+(AA25-$BR$15)^2+(AB25-$BS$15)^2+(AC25-$BT$15)^2) -> 2.9181066 | AG25: =IF(AD25=MIN(AD25:AF25),"Cluster 1",IF(AE25=MIN(AD25:AF25),"Cluster 2","Cluster 3")) -> Cluster 2 | AH25: =IF(E25="no","Not Applicable",IF(F25=0,"0 messages",IF(F25<=16,"1-16 messages",">16 messages"))) -> Not Applicable | AI25: =IF(T25="yes",I25,NA()) -> #N/A | AJ25: =IF(T25="no",I25,NA()) -> 32.3 | AK25: =D25&" - "&IF(Q25<=3,"Low",IF(Q25<=6,"Medium","High")) -> no - Medium | AL25: =IF(P25<=8.5,"Q1 - Low",IF(P25<=10.3,"Q2 - Medium",IF(P25<=12,"Q3 - High","Q4 - Very High"))) -> Q1 - Low | AM25: =IF(D25="yes",1,0) -> 0 | AN25: =IF(C25="area_code_415",1,0) -> 1 | AO25: =IF(C25="area_code_510",1,0) -> 0 | AP25: =S25 -> 0 | AQ25: =G25 -> 190 | BK25: Voice Mail Plan | BL25: Total Customers | BM25: Churned | BN25: Churn Rate
A26: HI | B26: 49 | C26: area_code_510 | D26: no | E26: no | F26: 0 | G26: 119.3 | H26: 117 | I26: 20.28 | J26: 215.1 | K26: 109 | L26: 18.28 | M26: 178.7 | N26: 90 | O26: 8.04 | P26: 11.1 | Q26: 1 | R26: 3 | S26: 1 | T26: no | U26: =IF(T26="yes",1,0) -> 0 | V26: =IF(S26>3,">3 calls","<=3 calls") -> <=3 calls | W26: =IF(B26<=_xlfn.QUARTILE.INC($B$2:$B$4251,1),"Q1", IF(B26<=_xlfn.QUARTILE.INC($B$2:$B$4251,2),"Q2", IF(B26<=_xlfn.QUARTILE.INC($B$2:$B$4251,3),"Q3","Q4"))) -> Q1 | X26: =IF(D26="no","Not Applicable",IF(R26>2.84,"High","Low")) -> Not Applicable | Y26: =IF(J26<=165,"Low",IF(J26<=233,"Medium","High")) -> Medium | Z26: =(G26-AVERAGE($G$2:$G$4251))/_xlfn.STDEV.S($G$2:$G$4251) -> -1.1286229 | AA26: =(J26-AVERAGE($J$2:$J$4251))/_xlfn.STDEV.S($J$2:$J$4251) -> 0.29703955 | AB26: =(M26-AVERAGE($M$2:$M$4251))/_xlfn.STDEV.S($M$2:$M$4251) -> -0.43349244 | AC26: =(P26-AVERAGE($P$2:$P$4251))/_xlfn.STDEV.S($P$2:$P$4251) -> 0.30576026 | AD26: =SQRT((Z26-$BQ$13)^2+(AA26-$BR$13)^2+(AB26-$BS$13)^2+(AC26-$BT$13)^2) -> 1.9299731 | AE26: =SQRT((Z26-$BQ$14)^2+(AA26-$BR$14)^2+(AB26-$BS$14)^2+(AC26-$BT$14)^2) -> 1.2819622 | AF26: =SQRT((Z26-$BQ$15)^2+(AA26-$BR$15)^2+(AB26-$BS$15)^2+(AC26-$BT$15)^2) -> 2.7499197 | AG26: =IF(AD26=MIN(AD26:AF26),"Cluster 1",IF(AE26=MIN(AD26:AF26),"Cluster 2","Cluster 3")) -> Cluster 2 | AH26: =IF(E26="no","Not Applicable",IF(F26=0,"0 messages",IF(F26<=16,"1-16 messages",">16 messages"))) -> Not Applicable | AI26: =IF(T26="yes",I26,NA()) -> #N/A | AJ26: =IF(T26="no",I26,NA()) -> 20.28 | AK26: =D26&" - "&IF(Q26<=3,"Low",IF(Q26<=6,"Medium","High")) -> no - Low | AL26: =IF(P26<=8.5,"Q1 - Low",IF(P26<=10.3,"Q2 - Medium",IF(P26<=12,"Q3 - High","Q4 - Very High"))) -> Q3 - High | AM26: =IF(D26="yes",1,0) -> 0 | AN26: =IF(C26="area_code_415",1,0) -> 0 | AO26: =IF(C26="area_code_510",1,0) -> 1 | AP26: =S26 -> 1 | AQ26: =G26 -> 119.3 | BK26: Yes | BL26: =COUNTIF($E:$E,"yes") -> 1112 | BM26: =COUNTIFS($E:$E,"yes",$T:$T,"yes") -> 82 | BN26: =BM26/BL26 -> 0.073741007
A27: NH | B27: 75 | C27: area_code_510 | D27: no | E27: no | F27: 0 | G27: 226.1 | H27: 105 | I27: 38.44 | J27: 201.5 | K27: 107 | L27: 17.13 | M27: 246.2 | N27: 98 | O27: 11.08 | P27: 10.3 | Q27: 5 | R27: 2.78 | S27: 1 | T27: no | U27: =IF(T27="yes",1,0) -> 0 | V27: =IF(S27>3,">3 calls","<=3 calls") -> <=3 calls | W27: =IF(B27<=_xlfn.QUARTILE.INC($B$2:$B$4251,1),"Q1", IF(B27<=_xlfn.QUARTILE.INC($B$2:$B$4251,2),"Q2", IF(B27<=_xlfn.QUARTILE.INC($B$2:$B$4251,3),"Q3","Q4"))) -> Q2 | X27: =IF(D27="no","Not Applicable",IF(R27>2.84,"High","Low")) -> Not Applicable | Y27: =IF(J27<=165,"Low",IF(J27<=233,"Medium","High")) -> Medium | Z27: =(G27-AVERAGE($G$2:$G$4251))/_xlfn.STDEV.S($G$2:$G$4251) -> 0.84870183 | AA27: =(J27-AVERAGE($J$2:$J$4251))/_xlfn.STDEV.S($J$2:$J$4251) -> 0.026390186 | AB27: =(M27-AVERAGE($M$2:$M$4251))/_xlfn.STDEV.S($M$2:$M$4251) -> 0.90702879 | AC27: =(P27-AVERAGE($P$2:$P$4251))/_xlfn.STDEV.S($P$2:$P$4251) -> 0.015915867 | AD27: =SQRT((Z27-$BQ$13)^2+(AA27-$BR$13)^2+(AB27-$BS$13)^2+(AC27-$BT$13)^2) -> 3.0232465 | AE27: =SQRT((Z27-$BQ$14)^2+(AA27-$BR$14)^2+(AB27-$BS$14)^2+(AC27-$BT$14)^2) -> 1.2425561 | AF27: =SQRT((Z27-$BQ$15)^2+(AA27-$BR$15)^2+(AB27-$BS$15)^2+(AC27-$BT$15)^2) -> 1.395662 | AG27: =IF(AD27=MIN(AD27:AF27),"Cluster 1",IF(AE27=MIN(AD27:AF27),"Cluster 2","Cluster 3")) -> Cluster 2 | AH27: =IF(E27="no","Not Applicable",IF(F27=0,"0 messages",IF(F27<=16,"1-16 messages",">16 messages"))) -> Not Applicable | AI27: =IF(T27="yes",I27,NA()) -> #N/A | AJ27: =IF(T27="no",I27,NA()) -> 38.44 | AK27: =D27&" - "&IF(Q27<=3,"Low",IF(Q27<=6,"Medium","High")) -> no - Medium | AL27: =IF(P27<=8.5,"Q1 - Low",IF(P27<=10.3,"Q2 - Medium",IF(P27<=12,"Q3 - High","Q4 - Very High"))) -> Q2 - Medium | AM27: =IF(D27="yes",1,0) -> 0 | AN27: =IF(C27="area_code_415",1,0) -> 0 | AO27: =IF(C27="area_code_510",1,0) -> 1 | AP27: =S27 -> 1 | AQ27: =G27 -> 226.1 | BK27: No | BL27: =COUNTIF($E:$E,"no") -> 3138 | BM27: =COUNTIFS($E:$E,"no",$T:$T,"yes") -> 516 | BN27: =BM27/BL27 -> 0.16443595
A28: AZ | B28: 12 | C28: area_code_408 | D28: no | E28: no | F28: 0 | G28: 249.6 | H28: 118 | I28: 42.43 | J28: 252.4 | K28: 119 | L28: 21.45 | M28: 280.2 | N28: 90 | O28: 12.61 | P28: 11.8 | Q28: 3 | R28: 3.19 | S28: 1 | T28: yes | U28: =IF(T28="yes",1,0) -> 1 | V28: =IF(S28>3,">3 calls","<=3 calls") -> <=3 calls | W28: =IF(B28<=_xlfn.QUARTILE.INC($B$2:$B$4251,1),"Q1", IF(B28<=_xlfn.QUARTILE.INC($B$2:$B$4251,2),"Q2", IF(B28<=_xlfn.QUARTILE.INC($B$2:$B$4251,3),"Q3","Q4"))) -> Q1 | X28: =IF(D28="no","Not Applicable",IF(R28>2.84,"High","Low")) -> Not Applicable | Y28: =IF(J28<=165,"Low",IF(J28<=233,"Medium","High")) -> High | Z28: =(G28-AVERAGE($G$2:$G$4251))/_xlfn.STDEV.S($G$2:$G$4251) -> 1.2837873 | AA28: =(J28-AVERAGE($J$2:$J$4251))/_xlfn.STDEV.S($J$2:$J$4251) -> 1.0393352 | AB28: =(M28-AVERAGE($M$2:$M$4251))/_xlfn.STDEV.S($M$2:$M$4251) -> 1.5822543 | AC28: =(P28-AVERAGE($P$2:$P$4251))/_xlfn.STDEV.S($P$2:$P$4251) -> 0.5593741 | AD28: =SQRT((Z28-$BQ$13)^2+(AA28-$BR$13)^2+(AB28-$BS$13)^2+(AC28-$BT$13)^2) -> 4.2981691 | AE28: =SQRT((Z28-$BQ$14)^2+(AA28-$BR$14)^2+(AB28-$BS$14)^2+(AC28-$BT$14)^2) -> 2.3547305 | AF28: =SQRT((Z28-$BQ$15)^2+(AA28-$BR$15)^2+(AB28-$BS$15)^2+(AC28-$BT$15)^2) -> 0.78438113 | AG28: =IF(AD28=MIN(AD28:AF28),"Cluster 1",IF(AE28=MIN(AD28:AF28),"Cluster 2","Cluster 3")) -> Cluster 3 | AH28: =IF(E28="no","Not Applicable",IF(F28=0,"0 messages",IF(F28<=16,"1-16 messages",">16 messages"))) -> Not Applicable | AI28: =IF(T28="yes",I28,NA()) -> 42.43 | AJ28: =IF(T28="no",I28,NA()) -> #N/A | AK28: =D28&" - "&IF(Q28<=3,"Low",IF(Q28<=6,"Medium","High")) -> no - Low | AL28: =IF(P28<=8.5,"Q1 - Low",IF(P28<=10.3,"Q2 - Medium",IF(P28<=12,"Q3 - High","Q4 - Very High"))) -> Q3 - High | AM28: =IF(D28="yes",1,0) -> 0 | AN28: =IF(C28="area_code_415",1,0) -> 0 | AO28: =IF(C28="area_code_510",1,0) -> 0 | AP28: =S28 -> 1 | AQ28: =G28 -> 249.6
A29: OK | B29: 57 | C29: area_code_408 | D29: no | E29: yes | F29: 25 | G29: 176.8 | H29: 94 | I29: 30.06 | J29: 195 | K29: 75 | L29: 16.58 | M29: 213.5 | N29: 116 | O29: 9.61 | P29: 8.3 | Q29: 4 | R29: 2.24 | S29: 0 | T29: no | U29: =IF(T29="yes",1,0) -> 0 | V29: =IF(S29>3,">3 calls","<=3 calls") -> <=3 calls | W29: =IF(B29<=_xlfn.QUARTILE.INC($B$2:$B$4251,1),"Q1", IF(B29<=_xlfn.QUARTILE.INC($B$2:$B$4251,2),"Q2", IF(B29<=_xlfn.QUARTILE.INC($B$2:$B$4251,3),"Q3","Q4"))) -> Q1 | X29: =IF(D29="no","Not Applicable",IF(R29>2.84,"High","Low")) -> Not Applicable | Y29: =IF(J29<=165,"Low",IF(J29<=233,"Medium","High")) -> Medium | Z29: =(G29-AVERAGE($G$2:$G$4251))/_xlfn.STDEV.S($G$2:$G$4251) -> -0.06405199 | AA29: =(J29-AVERAGE($J$2:$J$4251))/_xlfn.STDEV.S($J$2:$J$4251) -> -0.10296429 | AB29: =(M29-AVERAGE($M$2:$M$4251))/_xlfn.STDEV.S($M$2:$M$4251) -> 0.25762073 | AC29: =(P29-AVERAGE($P$2:$P$4251))/_xlfn.STDEV.S($P$2:$P$4251) -> -0.70869511 | AD29: =SQRT((Z29-$BQ$13)^2+(AA29-$BR$13)^2+(AB29-$BS$13)^2+(AC29-$BT$13)^2) -> 1.8295191 | AE29: =SQRT((Z29-$BQ$14)^2+(AA29-$BR$14)^2+(AB29-$BS$14)^2+(AC29-$BT$14)^2) -> 0.76375487 | AF29: =SQRT((Z29-$BQ$15)^2+(AA29-$BR$15)^2+(AB29-$BS$15)^2+(AC29-$BT$15)^2) -> 2.4123646 | AG29: =IF(AD29=MIN(AD29:AF29),"Cluster 1",IF(AE29=MIN(AD29:AF29),"Cluster 2","Cluster 3")) -> Cluster 2 | AH29: =IF(E29="no","Not Applicable",IF(F29=0,"0 messages",IF(F29<=16,"1-16 messages",">16 messages"))) -> >16 messages | AI29: =IF(T29="yes",I29,NA()) -> #N/A | AJ29: =IF(T29="no",I29,NA()) -> 30.06 | AK29: =D29&" - "&IF(Q29<=3,"Low",IF(Q29<=6,"Medium","High")) -> no - Medium | AL29: =IF(P29<=8.5,"Q1 - Low",IF(P29<=10.3,"Q2 - Medium",IF(P29<=12,"Q3 - High","Q4 - Very High"))) -> Q1 - Low | AM29: =IF(D29="yes",1,0) -> 0 | AN29: =IF(C29="area_code_415",1,0) -> 0 | AO29: =IF(C29="area_code_510",1,0) -> 0 | AP29: =S29 -> 0 | AQ29: =G29 -> 176.8 | BK29: Churn Status | BL29: Avg Intl Minutes | BM29: Avg Intl Charge
A30: AK | B30: 36 | C30: area_code_408 | D30: no | E30: yes | F30: 30 | G30: 146.3 | H30: 128 | I30: 24.87 | J30: 162.5 | K30: 80 | L30: 13.81 | M30: 129.3 | N30: 109 | O30: 5.82 | P30: 14.5 | Q30: 6 | R30: 3.92 | S30: 0 | T30: no | U30: =IF(T30="yes",1,0) -> 0 | V30: =IF(S30>3,">3 calls","<=3 calls") -> <=3 calls | W30: =IF(B30<=_xlfn.QUARTILE.INC($B$2:$B$4251,1),"Q1", IF(B30<=_xlfn.QUARTILE.INC($B$2:$B$4251,2),"Q2", IF(B30<=_xlfn.QUARTILE.INC($B$2:$B$4251,3),"Q3","Q4"))) -> Q1 | X30: =IF(D30="no","Not Applicable",IF(R30>2.84,"High","Low")) -> Not Applicable | Y30: =IF(J30<=165,"Low",IF(J30<=233,"Medium","High")) -> Low | Z30: =(G30-AVERAGE($G$2:$G$4251))/_xlfn.STDEV.S($G$2:$G$4251) -> -0.62873742 | AA30: =(J30-AVERAGE($J$2:$J$4251))/_xlfn.STDEV.S($J$2:$J$4251) -> -0.74973666 | AB30: =(M30-AVERAGE($M$2:$M$4251))/_xlfn.STDEV.S($M$2:$M$4251) -> -1.4145554 | AC30: =(P30-AVERAGE($P$2:$P$4251))/_xlfn.STDEV.S($P$2:$P$4251) -> 1.5375989 | AD30: =SQRT((Z30-$BQ$13)^2+(AA30-$BR$13)^2+(AB30-$BS$13)^2+(AC30-$BT$13)^2) -> 2.6099295 | AE30: =SQRT((Z30-$BQ$14)^2+(AA30-$BR$14)^2+(AB30-$BS$14)^2+(AC30-$BT$14)^2) -> 2.3070746 | AF30: =SQRT((Z30-$BQ$15)^2+(AA30-$BR$15)^2+(AB30-$BS$15)^2+(AC30-$BT$15)^2) -> 3.4399788 | AG30: =IF(AD30=MIN(AD30:AF30),"Cluster 1",IF(AE30=MIN(AD30:AF30),"Cluster 2","Cluster 3")) -> Cluster 2 | AH30: =IF(E30="no","Not Applicable",IF(F30=0,"0 messages",IF(F30<=16,"1-16 messages",">16 messages"))) -> >16 messages | AI30: =IF(T30="yes",I30,NA()) -> #N/A | AJ30: =IF(T30="no",I30,NA()) -> 24.87 | AK30: =D30&" - "&IF(Q30<=3,"Low",IF(Q30<=6,"Medium","High")) -> no - Medium | AL30: =IF(P30<=8.5,"Q1 - Low",IF(P30<=10.3,"Q2 - Medium",IF(P30<=12,"Q3 - High","Q4 - Very High"))) -> Q4 - Very High | AM30: =IF(D30="yes",1,0) -> 0 | AN30: =IF(C30="area_code_415",1,0) -> 0 | AO30: =IF(C30="area_code_510",1,0) -> 0 | AP30: =S30 -> 0 | AQ30: =G30 -> 146.3 | BK30: Yes | BL30: =AVERAGEIF($T:$T,"yes",$P:$P) -> 10.632441 | BM30: =AVERAGEIF($T:$T,"yes",$R:$R) -> 2.8712542
